2024-11-14 13:27:11 - INFO - Запуск бота...
2024-11-14 13:27:11 - INFO - База данных инициализирована
2024-11-14 13:27:11 - INFO - AuthHandler инициализирован
2024-11-14 13:27:11 - INFO - Приложение создано с токеном: 7892353308...
2024-11-14 13:27:11 - INFO - Добавление обработчика конверсации
2024-11-14 13:27:11 - INFO - Запуск процесса поллинга
2024-11-14 13:27:12 - ERROR - Критическая ошибка при запуске б��та: Cannot close a running event loop
2024-11-14 13:27:12 - ERROR - Cannot close a running event loop
Traceback (most recent call last):
  File "C:\Users\anxiety\AppData\Local\Programs\Python\Python313\Lib\site-packages\telegram\ext\_application.py", line 1063, in __run
    loop.run_until_complete(self.initialize())
    ~~~~~~~~~~~~~~~~~~~~~~~^^^^^^^^^^^^^^^^^^^
  File "C:\Users\anxiety\AppData\Local\Programs\Python\Python313\Lib\asyncio\base_events.py", line 697, in run_until_complete
    self._check_running()
    ~~~~~~~~~~~~~~~~~~~^^
  File "C:\Users\anxiety\AppData\Local\Programs\Python\Python313\Lib\asyncio\base_events.py", line 633, in _check_running
    raise RuntimeError('This event loop is already running')
RuntimeError: This event loop is already running

During handling of the above exception, another exception occurred:

Traceback (most recent call last):
  File "C:\Users\anxiety\AppData\Local\Programs\Python\Python313\Lib\site-packages\telegram\ext\_application.py", line 1084, in __run
    loop.run_until_complete(self.stop())
    ~~~~~~~~~~~~~~~~~~~~~~~^^^^^^^^^^^^^
  File "C:\Users\anxiety\AppData\Local\Programs\Python\Python313\Lib\asyncio\base_events.py", line 697, in run_until_complete
    self._check_running()
    ~~~~~~~~~~~~~~~~~~~^^
  File "C:\Users\anxiety\AppData\Local\Programs\Python\Python313\Lib\asyncio\base_events.py", line 633, in _check_running
    raise RuntimeError('This event loop is already running')
RuntimeError: This event loop is already running

During handling of the above exception, another exception occurred:

Traceback (most recent call last):
  File "C:\Users\anxiety\.cursor-tutor\main.py", line 92, in main
    await application.run_polling(allowed_updates=Update.ALL_TYPES)
          ~~~~~~~~~~~~~~~~~~~~~~~^^^^^^^^^^^^^^^^^^^^^^^^^^^^^^^^^^
  File "C:\Users\anxiety\AppData\Local\Programs\Python\Python313\Lib\site-packages\telegram\ext\_application.py", line 865, in run_polling
    return self.__run(
           ~~~~~~~~~~^
        updater_coroutine=self.updater.start_polling(
        ^^^^^^^^^^^^^^^^^^^^^^^^^^^^^^^^^^^^^^^^^^^^^
    ...<12 lines>...
        stop_signals=stop_signals,
        ^^^^^^^^^^^^^^^^^^^^^^^^^^
    )
    ^
  File "C:\Users\anxiety\AppData\Local\Programs\Python\Python313\Lib\site-packages\telegram\ext\_application.py", line 1093, in __run
    loop.close()
    ~~~~~~~~~~^^
  File "C:\Users\anxiety\AppData\Local\Programs\Python\Python313\Lib\asyncio\proactor_events.py", line 684, in close
    raise RuntimeError("Cannot close a running event loop")
RuntimeError: Cannot close a running event loop
