2024-11-14 14:21:21 - INFO - Запуск бота...
2024-11-14 14:21:21 - INFO - База данных инициализирована
2024-11-14 14:21:21 - INFO - AuthHandler инициализирован
2024-11-14 14:21:22 - INFO - Приложение создано с токеном: 7892353308...
2024-11-14 14:21:22 - INFO - Добавление обработчика конверсации
2024-11-14 14:21:22 - INFO - Запуск процесса поллинга
2024-11-14 14:21:25 - DEBUG - Вызвана команда start пользователем 6121074409
2024-11-14 14:21:25 - DEBUG - Отправлено стартовое меню
2024-11-14 14:21:42 - ERROR - Произошла ошибка: name 'user_id' is not defined
2024-11-14 14:21:42 - ERROR - name 'user_id' is not defined
Traceback (most recent call last):
  File "C:\Users\anxiety\AppData\Local\Programs\Python\Python313\Lib\site-packages\telegram\ext\_application.py", line 1319, in process_update
    await coroutine
  File "C:\Users\anxiety\AppData\Local\Programs\Python\Python313\Lib\site-packages\telegram\ext\_handlers\conversationhandler.py", line 844, in handle_update
    new_state: object = await handler.handle_update(
                        ^^^^^^^^^^^^^^^^^^^^^^^^^^^^
        update, application, handler_check_result, context
        ^^^^^^^^^^^^^^^^^^^^^^^^^^^^^^^^^^^^^^^^^^^^^^^^^^
    )
    ^
  File "C:\Users\anxiety\AppData\Local\Programs\Python\Python313\Lib\site-packages\telegram\ext\_handlers\basehandler.py", line 158, in handle_update
    return await self.callback(update, context)
           ^^^^^^^^^^^^^^^^^^^^^^^^^^^^^^^^^^^^
  File "C:\Users\anxiety\.cursor-tutor\handlers\auth_handler.py", line 417, in handle_position_selection
    return await self.show_users_list(update, context)
           ^^^^^^^^^^^^^^^^^^^^^^^^^^^^^^^^^^^^^^^^^^^
  File "C:\Users\anxiety\.cursor-tutor\handlers\auth_handler.py", line 372, in show_users_list
    return await self.show_menu(update, context)
           ^^^^^^^^^^^^^^^^^^^^^^^^^^^^^^^^^^^^^
  File "C:\Users\anxiety\.cursor-tutor\handlers\auth_handler.py", line 89, in show_menu
    profile_text = await self.format_profile_info(user_data)
                   ^^^^^^^^^^^^^^^^^^^^^^^^^^^^^^^^^^^^^^^^^
  File "C:\Users\anxiety\.cursor-tutor\handlers\auth_handler.py", line 69, in format_profile_info
    admin_stores = self.db.get_admin_stores(user_id)
                                            ^^^^^^^
NameError: name 'user_id' is not defined
2024-11-14 14:21:44 - ERROR - Произошла ошибка: name 'user_id' is not defined
2024-11-14 14:21:44 - ERROR - name 'user_id' is not defined
Traceback (most recent call last):
  File "C:\Users\anxiety\AppData\Local\Programs\Python\Python313\Lib\site-packages\telegram\ext\_application.py", line 1319, in process_update
    await coroutine
  File "C:\Users\anxiety\AppData\Local\Programs\Python\Python313\Lib\site-packages\telegram\ext\_handlers\conversationhandler.py", line 844, in handle_update
    new_state: object = await handler.handle_update(
                        ^^^^^^^^^^^^^^^^^^^^^^^^^^^^
        update, application, handler_check_result, context
        ^^^^^^^^^^^^^^^^^^^^^^^^^^^^^^^^^^^^^^^^^^^^^^^^^^
    )
    ^
  File "C:\Users\anxiety\AppData\Local\Programs\Python\Python313\Lib\site-packages\telegram\ext\_handlers\basehandler.py", line 158, in handle_update
    return await self.callback(update, context)
           ^^^^^^^^^^^^^^^^^^^^^^^^^^^^^^^^^^^^
  File "C:\Users\anxiety\.cursor-tutor\handlers\auth_handler.py", line 417, in handle_position_selection
    return await self.show_users_list(update, context)
           ^^^^^^^^^^^^^^^^^^^^^^^^^^^^^^^^^^^^^^^^^^^
  File "C:\Users\anxiety\.cursor-tutor\handlers\auth_handler.py", line 372, in show_users_list
    return await self.show_menu(update, context)
           ^^^^^^^^^^^^^^^^^^^^^^^^^^^^^^^^^^^^^
  File "C:\Users\anxiety\.cursor-tutor\handlers\auth_handler.py", line 89, in show_menu
    profile_text = await self.format_profile_info(user_data)
                   ^^^^^^^^^^^^^^^^^^^^^^^^^^^^^^^^^^^^^^^^^
  File "C:\Users\anxiety\.cursor-tutor\handlers\auth_handler.py", line 69, in format_profile_info
    admin_stores = self.db.get_admin_stores(user_id)
                                            ^^^^^^^
NameError: name 'user_id' is not defined
2024-11-14 14:22:16 - ERROR - Произошла ошибка: name 'user_id' is not defined
2024-11-14 14:22:16 - ERROR - name 'user_id' is not defined
Traceback (most recent call last):
  File "C:\Users\anxiety\AppData\Local\Programs\Python\Python313\Lib\site-packages\telegram\ext\_application.py", line 1319, in process_update
    await coroutine
  File "C:\Users\anxiety\AppData\Local\Programs\Python\Python313\Lib\site-packages\telegram\ext\_handlers\conversationhandler.py", line 844, in handle_update
    new_state: object = await handler.handle_update(
                        ^^^^^^^^^^^^^^^^^^^^^^^^^^^^
        update, application, handler_check_result, context
        ^^^^^^^^^^^^^^^^^^^^^^^^^^^^^^^^^^^^^^^^^^^^^^^^^^
    )
    ^
  File "C:\Users\anxiety\AppData\Local\Programs\Python\Python313\Lib\site-packages\telegram\ext\_handlers\basehandler.py", line 158, in handle_update
    return await self.callback(update, context)
           ^^^^^^^^^^^^^^^^^^^^^^^^^^^^^^^^^^^^
  File "C:\Users\anxiety\.cursor-tutor\handlers\auth_handler.py", line 417, in handle_position_selection
    return await self.show_users_list(update, context)
           ^^^^^^^^^^^^^^^^^^^^^^^^^^^^^^^^^^^^^^^^^^^
  File "C:\Users\anxiety\.cursor-tutor\handlers\auth_handler.py", line 372, in show_users_list
    return await self.show_menu(update, context)
           ^^^^^^^^^^^^^^^^^^^^^^^^^^^^^^^^^^^^^
  File "C:\Users\anxiety\.cursor-tutor\handlers\auth_handler.py", line 89, in show_menu
    profile_text = await self.format_profile_info(user_data)
                   ^^^^^^^^^^^^^^^^^^^^^^^^^^^^^^^^^^^^^^^^^
  File "C:\Users\anxiety\.cursor-tutor\handlers\auth_handler.py", line 69, in format_profile_info
    admin_stores = self.db.get_admin_stores(user_id)
                                            ^^^^^^^
NameError: name 'user_id' is not defined
2024-11-14 14:22:18 - DEBUG - Вызвана команда start пользователем 6121074409
2024-11-14 14:22:18 - DEBUG - Отправлено стартовое меню
2024-11-14 14:22:21 - ERROR - Произошла ошибка: name 'user_id' is not defined
2024-11-14 14:22:21 - ERROR - name 'user_id' is not defined
Traceback (most recent call last):
  File "C:\Users\anxiety\AppData\Local\Programs\Python\Python313\Lib\site-packages\telegram\ext\_application.py", line 1319, in process_update
    await coroutine
  File "C:\Users\anxiety\AppData\Local\Programs\Python\Python313\Lib\site-packages\telegram\ext\_handlers\conversationhandler.py", line 844, in handle_update
    new_state: object = await handler.handle_update(
                        ^^^^^^^^^^^^^^^^^^^^^^^^^^^^
        update, application, handler_check_result, context
        ^^^^^^^^^^^^^^^^^^^^^^^^^^^^^^^^^^^^^^^^^^^^^^^^^^
    )
    ^
  File "C:\Users\anxiety\AppData\Local\Programs\Python\Python313\Lib\site-packages\telegram\ext\_handlers\basehandler.py", line 158, in handle_update
    return await self.callback(update, context)
           ^^^^^^^^^^^^^^^^^^^^^^^^^^^^^^^^^^^^
  File "C:\Users\anxiety\.cursor-tutor\handlers\auth_handler.py", line 269, in check_auth_barcode
    profile_text = await self.format_profile_info(user_data)
                   ^^^^^^^^^^^^^^^^^^^^^^^^^^^^^^^^^^^^^^^^^
  File "C:\Users\anxiety\.cursor-tutor\handlers\auth_handler.py", line 69, in format_profile_info
    admin_stores = self.db.get_admin_stores(user_id)
                                            ^^^^^^^
NameError: name 'user_id' is not defined
2024-11-14 14:22:34 - INFO - Бот остановлен пользователем
